Workbook

Sheet Cover Page
A1: Republic of the Philippines Provincial Government of Batangas PROVINCIAL HEALTH OFFICE Brgy. Kumintang Ibaba, Batangas City E-mail: pho@batangas.gov.ph | Tel No. (043) 740-2832; (043) 723-2592
A2: PROJECT PROCUREMENT MANAGEMENT PLAN 2025
A3: END USER/UNIT: | C3: PROVINCIAL HEALTH OFFICE - PROPER
A4: CHARGED TO: | C4: GENERAL FUND - PHO - PROPER
A6: ACCOUNT CODE | C6: ACCOUNT NAME | D6: AMOUNT
A7: ='PHO-PROPER FUND'!A10 -> 50201010 | C7: TRAVELING EXPENSES - LOCAL | D7: =#REF! -> #REF!
A8: 50202010 | C8: TRAINING EXPENSES | D8: =#REF! -> #REF!
A9: 50203010 | C9: OFFICE SUPPLIES EXPENSES | D9: =#REF! -> #REF!
A10: 50203020 | C10: ACCOUNTABLE FORMS EXPENSES | D10: =#REF! -> #REF!
A11: 50203030 | C11: NON-ACCOUNTABLE FORMS EXPENSES | D11: ='PHO-PROPER FUND'!H14 -> 475000
A12: 50203070 | C12: DRUGS AND MEDICINES EXPENSES | D12: ='PHO-PROPER FUND'!H354 -> 28500000
A13: 50203080 | C13: MEDICAL, DENTAL, LABORATORY SUPPLIES EXPENSES | D13: ='PHO-PROPER FUND'!H568 -> 28500000
A14: 50203090 | C14: FUEL, OIL AND LUBRICANTS EXPENSES | D14: ='PHO-PROPER FUND'!H16 -> 3500000
A15: 50203990 | C15: OTHER SUPPLIES AND MATERIALS EXPENSES | D15: ='PHO-PROPER FUND'!H871 -> 1700000
C16: WATER EXPENSES | D16: =0 -> 0
C17: ELECTRICITY EXPENSES | D17: =0 -> 0
C18: CABLE, SATELLITE, TELEGRAPH AND RADIO EXPENSES | D18: ='PHO-PROPER FUND'!H22 -> 20000
A19: 50206020 | C19: PRIZES | D19: ='PHO-PROPER FUND'!H24 -> 210000
A20: 50213040 | C20: REPAIRS AND MAINTENANCE - BUILDING AND OTHER STRUCTURES | D20: ='PHO-PROPER FUND'!H27 -> 3200000
A21: 50213050 | C21: REPAIRS AND MAINTENANCE - MACHINERY AND EQUIPMENT | D21: ='PHO-PROPER FUND'!H29 -> 400000
A22: 50213060 | C22: REPAIRS AND MAINTENANCE - TRANSPORTATION EQUIPMENT | D22: ='PHO-PROPER FUND'!H31 -> 750000
C23: TAXES, DUTIES AND LICENSES | D23: ='PHO-PROPER FUND'!#REF! -> #ERROR!
C24: FIDELITY BOND PREMIUMS | D24: ='PHO-PROPER FUND'!#REF! -> #ERROR!
A25: 50299020 | C25: PRINTING AND PUBLICATION EXPENSES
A26: 50299030 | C26: REPRESENTATION EXPENSES
C27: TRANSPORTATION & DELIVERY EXPENSES | D27: ='PHO-PROPER FUND'!H39 -> 260000
C28: RENT EXPENSES
C29: SUBSCRIPTION EXPENSES
A30: 50299990 | C30: OTHER MAINTENANCE AND OPERATING EXPENSES
A31: 10704990 | C31: CAPITAL OUTLAY - OTHER STRUCTURES
A32: 10705010 | C32: CAPITAL OUTLAY - MACHINERY
A33: 10705020 | C33: CAPITAL OUTLAY - OFFICE EQUIPMENT
A34: 10705030 | C34: CAPITAL OUTLAY - INFORMATION AND COMMUNICATION TECHNOLOGY EQUIPMENT
A35: 10705070 | C35: CAPITAL OUTLAY - COMMUNICATION EQUIPMENT
A36: 10705110 | C36: CAPITAL OUTLAY - MEDICAL EQUIPMENT
A37: 10707010 | C37: CAPITAL OUTLAY - FURNITURE AND FIXTURES
A38: 50203130 | C38: CHEMICAL AND FILTERING SUPPLIES EXPENSE
A39: 50211030 | C39: CONSULTANCY SERVICES
A40: 50212010 | C40: ENVIRONMENTAL AND SANITARY SERVICES
A41: 50299080 | C41: DONATIONS
...

Sheet PHO-PROPER GEN. FUND
A1: Republic of the Philippines Provincial Government of Batangas PROVINCIAL HEALTH OFFICE Brgy. Kumintang Ibaba, Batangas City E-mail: pho@batangas.gov.ph | Tel No. (043) 740-2832; (043) 723-2592
A2: PROJECT PROCUREMENT MANAGEMENT PLAN 2026
A3: END USER/UNIT: | C3: PROVINCIAL HEALTH OFFICE - PROPER
A4: CHARGED TO: | C4: GENERAL FUND - PHO-PROPER
A6: CODE | B6: GENERAL DESCRIPTION | E6: QTY | F6: UNIT | G6: UNIT PRICE | H6: ESTIMATED BUDGET | I6: MODE OF PROCUREMENT | J6: SCHEDULE / MILESTONE OF ACTIVITIES
J7: JAN | K7: FEB | L7: MAR | M7: APR | N7: MAY | O7: JUN | P7: JUL | Q7: AUG | R7: SEP | S7: OCT | T7: NOV | U7: DEC
C8: MAINTENANCE AND OTHER OPERATING EXPENSES
A10: 50201010 | C10: TRAVELING EXPENSES - LOCAL | H10: 2000000 | J10: x | K10: x | L10: x | M10: x | N10: x | O10: x | P10: x | Q10: x | R10: x | S10: x | T10: x | U10: x
A12: ='Cover Page'!A10 -> 50203020 | C12: ACCOUNTABLE FORMS EXPENSES | H12: 10000 | I12: BIDDING/SMALL VALUE | J12: x | K12: x | L12: x | M12: x | N12: x | O12: x | P12: x | Q12: x | R12: x | S12: x | T12: x | U12: x
C13: General Form No. 51-A (Official Receipt)
A15: ='Cover Page'!A11 -> 50203030 | C15: NON-ACCOUNTABLE FORMS EXPENSES | H15: 75000 | I15: BIDDING/SMALL VALUE | J15: x | K15: x | L15: x | M15: x | N15: x | O15: x | P15: x | Q15: x | R15: x | S15: x | T15: x | U15: x
C16: Medical/Treatment/Vaccination Forms
A18: ='Cover Page'!A14 -> 50203090 | C18: FUEL, OIL AND LUBRICANTS EXPENSES | H18: 3500000 | I18: BIDDING/SMALL VALUE | J18: x | K18: x | L18: x | M18: x | N18: x | O18: x | P18: x | Q18: x | R18: x | S18: x | T18: x | U18: x
A20: 50204010 | C20: WATER EXPENSES | H20: 10000000 | J20: x | K20: x | L20: x | M20: x | N20: x | O20: x | P20: x | Q20: x | R20: x | S20: x | T20: x | U20: x
A22: 50204020 | C22: ELECTRICITY EXPENSES | H22: 50000000 | J22: x | K22: x | L22: x | M22: x | N22: x | O22: x | P22: x | Q22: x | R22: x | S22: x | T22: x | U22: x
A24: 50205020 | C24: TELEPHONE EXPENSES | H24: 316000 | J24: x | K24: x | L24: x | M24: x | N24: x | O24: x | P24: x | Q24: x | R24: x | S24: x | T24: x | U24: x
A26: 50205030 | C26: INTERNET SUBSCRIPTION EXPENSES | H26: 300000 | J26: x | K26: x | L26: x | M26: x | N26: x | O26: x | P26: x | Q26: x | R26: x | S26: x | T26: x | U26: x
A28: 50205040 | C28: CABLE, SATELLITE, TELEGRAPH AND RADIO EXPENSES | H28: 20000 | J28: x | K28: x | L28: x | M28: x | N28: x | O28: x | P28: x | Q28: x | R28: x | S28: x | T28: x | U28: x
A30: ='Cover Page'!A19 -> 50206020 | C30: PRIZES | H30: 210000 | J30: x | K30: x | L30: x | M30: x | N30: x | O30: x | P30: x | Q30: x | R30: x | S30: x | T30: x | U30: x
C31: REPAIRS AND MAINTENANCE
A32: ='Cover Page'!A20 -> 50213040 | C32: BUILDING AND OTHER STRUCTURES | H32: 1600000 | I32: BIDDING/SMALL VALUE | J32: x | K32: x | L32: x | M32: x | N32: x | O32: x | P32: x | Q32: x | R32: x | S32: x | T32: x | U32: x
A34: ='Cover Page'!A21 -> 50213050 | C34: MACHINERY AND EQUIPMENT | H34: 900000 | I34: BIDDING/SMALL VALUE | J34: x | K34: x | L34: x | M34: x | N34: x | O34: x | P34: x | Q34: x | R34: x | S34: x | T34: x | U34: x
A36: ='Cover Page'!A22 -> 50213060 | C36: TRANSPORTATION EQUIPMENT | H36: 950000 | I36: BIDDING/SMALL VALUE | J36: x | K36: x | L36: x | M36: x | N36: x | O36: x | P36: x | Q36: x | R36: x | S36: x | T36: x | U36: x
A38: 50213210 | C38: SEMI-EXPENDABLE MACHINERY AND EQUIPMENT | H38: 100000 | I38: BIDDING/SMALL VALUE | J38: x | K38: x | L38: x | M38: x | N38: x | O38: x | P38: x | Q38: x | R38: x | S38: x | T38: x | U38: x
A40: 50216010 | C40: TAXES, DUTIES, AND LICENSES | H40: 25000 | J40: x | K40: x | L40: x | M40: x | N40: x | O40: x | P40: x | Q40: x | R40: x | S40: x | T40: x | U40: x
A42: 50216020 | C42: FIDELITY BOND PREMIUMS | H42: 100000 | J42: x | K42: x | L42: x | M42: x | N42: x | O42: x | P42: x | Q42: x | R42: x | S42: x | T42: x | U42: x
A44: 50299020 | C44: PRINTING AND PUBLICATION EXPENSES | H44: 150000 | I44: BIDDING/SMALL VALUE | J44: x | K44: x | L44: x | M44: x | N44: x | O44: x | P44: x | Q44: x | R44: x | S44: x | T44: x | U44: x
C45: Posters, flyers, and other IEC materials
C46: Immunization/Vaccination/Treatment/Other Medical Cards
C47: Leaflets, pamphlets
C48: Blood Donor's ID Card
A50: 50299040 | C50: TRANSPORTATION & DELIVERY EXPENSES | H50: 160000 | I50: BIDDING/SMALL VALUE | J50: x | K50: x | L50: x | M50: x | N50: x | O50: x | P50: x | Q50: x | R50: x | S50: x | T50: x | U50: x
A52: ='Cover Page'!A8 -> 50202010 | C52: TRAINING EXPENSES | H52: 250000 | I52: BIDDING/SMALL VALUE | J52: x | K52: x | L52: x | M52: x | N52: x | O52: x | P52: x | Q52: x | R52: x | S52: x | T52: x | U52: x
C53: Meals and Accomodation/ Food and Venue
C54: Training Materials
A56: 50203010 | C56: OFFICE SUPPLIES EXPENSES | H56: 3000000 | I56: BIDDING/SMALL VALUE
C57: All Purpose Sticker A4 10's/pack | E57: 100 | F57: pack | G57: 77 | H57: =E57*G57 -> 7700 | K57: =E57/2 -> 50 | P57: =E57/2 -> 50
C58: AntiVirus Software With 2 years License | E58: 32 | F58: piece | G58: 4000 | H58: =E58*G58 -> 128000 | K58: =E58/2 -> 16 | P58: =E58/2 -> 16
C59: Arch File Vertical, 2-Ring Binder, 2" Side, Long, Black | E59: 50 | F59: piece | G59: 200 | H59: =E59*G59 -> 10000 | K59: =E59/2 -> 25 | P59: =E59/2 -> 25
C60: Arch File Vertical, 2-Ring Binder, 2" Side, A4, Black | E60: 30 | F60: piece | G60: 200 | H60: =E60*G60 -> 6000 | K60: =E60/2 -> 15 | P60: =E60/2 -> 15
...

Sheet ISVWP FUND
A1: Republic of the Philippines Provincial Government of Batangas PROVINCIAL HEALTH OFFICE Brgy. Kumintang Ibaba, Batangas City E-mail: pho@batangas.gov.ph | Tel No. (043) 740-2832; (043) 723-2592
A2: PROJECT PROCUREMENT MANAGEMENT PLAN 2026
A3: END USER/UNIT: | C3: PROVINCIAL HEALTH OFFICE
A4: CHARGED TO: | C4: INTEGRATED SERVICE VOLUNTEER WORKERS PROGRAM
A6: CODE | B6: GENERAL DESCRIPTION | E6: QTY | F6: UNIT | G6: UNIT PRICE | H6: ESTIMATED BUDGET | I6: MODE OF PROCUREMENT | J6: SCHEDULE / MILESTONE OF ACTIVITIES
J7: JAN | K7: FEB | L7: MAR | M7: APR | N7: MAY | O7: JUN | P7: JUL | Q7: AUG | R7: SEP | S7: OCT | T7: NOV | U7: DEC
C8: MAINTENANCE AND OTHER OPERATING EXPENSES
A10: 50299080 | C10: DONATIONS | H10: 101420000
C11: Honorarium of Volunteer Workers
C12: -Barangay Health Workers | H12: 72000000 | L12: x | O12: x | R12: x | U12: x
C13: -Barangay Nutrition Scholars | H13: 18000000 | L13: x | O13: x | R13: x | U13: x
C16: Additional Incentives for BHW and BNS Presidents | H16: 852000 | L16: x | O16: x | R16: x | U16: x
C18: Cash Incentive for Provincial Service Incentive (PSI) applicants - retired BHWs and BNSs | H18: 815400 | J18: x | K18: x | L18: x | M18: x | N18: x | O18: x | P18: x | Q18: x | R18: x | S18: x | T18: x | U18: x
C20: T shirt for BHWs and BNS | H20: 3750000 | I20: BIDDING | L20: x
C21: Transportation Allowance of BHWs and BNSs | H21: 6000000 | L21: x | O21: x | R21: x | U21: x
E23: GRAND TOTAL | H23: =SUM(H12:H21) -> 101417400
A27: Prepared by: | F27: Recommending Approval: | P27: Approved by:
A31: CYNTHIA E. LACABA | F31: GERALD G. ALDAY, MD., MPA., FPSMSI | P31: HON. VILMA SANTOS RECTO
A32: Nutrition Officer IV | F32: OIC - Provincial Health Officer | P32: Provincial Governor

Sheet CAPITAL OUTLAY
A1: Republic of the Philippines Provincial Government of Batangas PROVINCIAL HEALTH OFFICE Brgy. Kumintang Ibaba, Batangas City E-mail: pho@batangas.gov.ph | Tel No. (043) 740-2832; (043) 723-2592
A2: PROJECT PROCUREMENT MANAGEMENT PLAN 2025
A3: END USER/UNIT: | C3: PROVINCIAL HEALTH OFFICE - PROPER
A4: CHARGED TO: | C4: GENERAL FUND - PHO-PROPER
A6: CODE | B6: GENERAL DESCRIPTION | E6: QTY | F6: UNIT | G6: UNIT PRICE | H6: ESTIMATED BUDGET | I6: MODE OF PROCUREMENT | J6: SCHEDULE / MILESTONE OF ACTIVITIES
J7: JAN | K7: FEB | L7: MAR | M7: APR | N7: MAY | O7: JUN | P7: JUL | Q7: AUG | R7: SEP | S7: OCT | T7: NOV | U7: DEC
C8: CAPITAL OUTLAY
A10: 10705010 | C10: MACHINERY | H10: 3000000 | I10: BIDDING/SHOPPING/ SMALL VALUE
C11: Washing Machine | D11: 15.0kg Digital Inverter, Fully Automatic Top Load | E11: 10 | F11: unit | G11: 50200 | H11: =E11*G11 -> 502000
C12: Dryer Industrial Type | D12: 9 kg | E12: 5 | F12: unit | G12: 59000 | H12: =E12*G12 -> 295000
C13: Floor Polisher | D13: Industrial Type, Wet and Dry | E13: 6 | F13: unit | G13: 50600 | H13: =E13*G13 -> 303600
C14: Food Conveyor | D14: With Trays, 2-doors, stainless, 30 trays capacity | E14: 14 | F14: unit | G14: 85000 | H14: =E14*G14 -> 1190000
C15: Sound System | E15: 1 | F15: unit | G15: 52000 | H15: =E15*G15 -> 52000
C16: Steamer | D16: for laundry | E16: 1 | F16: unit | G16: 60000 | H16: =E16*G16 -> 60000
C17: Dish Sterilizer | D17: HDS 88 CUFT | E17: 1 | F17: unit | G17: 50100 | H17: =E17*G17 -> 50100
C18: Refrigerator | D18: 2-Door, Inverter | E18: 4 | F18: unit | G18: 56000 | H18: =E18*G18 -> 224000
C20: Total | H20: =SUM(H11:H19) -> 2676700
C22: For use of Provincial Health Care Facility | G22: =SUM(H23) -> 50000 | I22: BIDDING/SHOPPING/ SMALL VALUE
C23: Airconditioning Unit | D23: 2 HP Window Type (Inverter) | E23: 2 | F23: unit | G23: 25000 | H23: =E23*G23 -> 50000 | K23: =E23 -> 2
C25: For use of Apacible Memorial District Hospital | G25: =SUM(H26:H33) -> 519000 | I25: BIDDING/SHOPPING/ SMALL VALUE
C26: 15.0kg Digital Inverter, Fully Automatic Top Load Washing Machine | D26: Washer Type:Top Load Capacity:15.0 kg Spin Speed:700 rpm Pulsator:PP Dual Storm Voltage/Frequency: 230V/60Hz Gross Weight: 45.0 kg Net Weight: 41.0 kg Gross Dimensions (WxHxD) : 660 x 1165 x 740 mm Net Dimensions (WxHxD) : 610 x 1089 x 675 mm | E26: 2 | F26: unit | G26: 20000 | H26: =E26*G26 -> 40000 | K26: =E26 -> 2
C27: Ceiling Fan | E27: 10 | F27: unit | G27: 3000 | H27: =E27*G27 -> 30000 | K27: =E27 -> 10
C28: Stand Fan | E28: 5 | F28: unit | G28: 3000 | H28: =E28*G28 -> 15000 | K28: =E28 -> 5
C29: Wall Fan | E29: 10 | F29: unit | G29: 2000 | H29: =E29*G29 -> 20000 | K29: =E29 -> 10
C30: Industrial fan | E30: 3 | F30: unit | G30: 6000 | H30: =E30*G30 -> 18000 | K30: =E30 -> 3
C31: Airconditioning Unit, 2HP, Window-Type | E31: 4 | F31: unit | G31: 35000 | H31: =E31*G31 -> 140000 | K31: =E31 -> 4
C32: Airconditioning Unit, Floor mounted, 3TR | E32: 2 | F32: unit | G32: 120000 | H32: =E32*G32 -> 240000 | K32: =E32 -> 2
C33: Power Spray for cleaning and washing | E33: 2 | F33: unit | G33: 8000 | H33: =E33*G33 -> 16000 | K33: =E33 -> 2
C35: For use of Batangas Provincial Hospital | G35: =SUM(H36:H41) -> 517600 | I35: BIDDING/SHOPPING/ SMALL VALUE
C36: Dryer | D36: Industrial Type, 9 kg | E36: 1 | F36: unit | G36: 59000 | H36: =E36*G36 -> 59000 | K36: =E36 -> 1
C37: Fire Extinguisher | D37: 10 lbs | E37: 19 | F37: unit | G37: 9000 | H37: =E37*G37 -> 171000 | K37: =E37 -> 19
C38: Fire Extinguisher | D38: 50 lbs | E38: 5 | F38: unit | G38: 20000 | H38: =E38*G38 -> 100000 | K38: =E38 -> 5
C39: Floor Polisher | D39: Industrial Type, Wet and Dry | E39: 1 | F39: unit | G39: 50600 | H39: =E39*G39 -> 50600 | K39: =E39 -> 1
C40: Food Conveyor | D40: With Trays, 2-doors, stainless, 30 trays capacity | E40: 1 | F40: unit | G40: 85000 | H40: =E40*G40 -> 85000 | K40: =E40 -> 1
C41: Sound System | E41: 1 | F41: unit | G41: 52000 | H41: =E41*G41 -> 52000 | K41: =E41 -> 1
C43: For use of Calatagan Medicare Hospital | G43: =SUM(H44:H46) -> 170000 | I43: BIDDING/SHOPPING/ SMALL VALUE
C44: Nebulizer Pulmo Aide | E44: 5 | F44: unit | G44: 15000 | H44: =E44*G44 -> 75000 | K44: =E44 -> 5
C45: BP Aneroid APG Adult | E45: 10 | F45: unit | G45: 2000 | H45: =E45*G45 -> 20000 | K45: =E45 -> 10
C46: BP Aneroid With Wheels | E46: 5 | F46: unit | G46: 15000 | H46: =E46*G46 -> 75000 | K46: =E46 -> 5
C47: Pulse Oximeter Fingertip | E47: 10 | F47: unit | G47: 3000 | H47: =E47*G47 -> 30000 | K47: =E47 -> 10
...

Sheet NUTRITION DEVT FUND
A1: Republic of the Philippines Provincial Government of Batangas PROVINCIAL HEALTH OFFICE Brgy. Kumintang Ibaba, Batangas City E-mail: pho@batangas.gov.ph | Tel No. (043) 740-2832; (043) 723-2592
A2: PROJECT PROCUREMENT MANAGEMENT PLAN 2026
A3: END USER/UNIT: | C3: PROVINCIAL HEALTH OFFICE - PROPER
A4: CHARGED TO: | C4: NUTRITION DEVELOPMENT PROGRAM
A6: CODE | B6: GENERAL DESCRIPTION | D6: QTY | E6: UNIT | F6: UNIT PRICE | G6: ESTIMATED BUDGET | H6: MODE OF PROCUREMENT | I6: SCHEDULE / MILESTONE OF ACTIVITIES
I7: JAN | J7: FEB | K7: MAR | L7: APR | M7: MAY | N7: JUN | O7: JUL | P7: AUG | Q7: SEP | R7: OCT | S7: NOV | T7: DEC
C8: MAINTENANCE AND OTHER OPERATING EXPENSES
A10: 50202010 | C10: TRAINING EXPENSES | G10: 600000 | H10: BIDDING/SMALL VALUE
C11: Registration Fee (Attendance to Seminars, Trainings, Conventions, etc) | I11: x | J11: x | K11: x | L11: x | M11: x | N11: x | O11: x | P11: x | Q11: x | R11: x | S11: x | T11: x
C12: Meals and Snacks of Participants | I12: x | J12: x | K12: x | L12: x | M12: x | N12: x | O12: x | P12: x | Q12: x | R12: x | S12: x | T12: x
C13: Honorarium of Resource Speakers, Lecturers and Trainors | I13: x | J13: x | K13: x | L13: x | M13: x | N13: x | O13: x | P13: x | Q13: x | R13: x | S13: x | T13: x
C14: Total | G14: =G10 -> 600000
A17: 50203010 | C17: OFFICE SUPPLIES EXPENSES | G17: 250000 | H17: BIDDING/SMALL VALUE
B18: 1 | C18: Ballpen, black, 12's/box | D18: 50 | E18: box | F18: 110.5 | G18: =D18*F18 -> 5525 | L18: 25 | P18: 25
B19: 2 | C19: Battery, AA by 4's / pack | D19: 10 | E19: pack | F19: 148 | G19: =D19*F19 -> 1480 | L19: 5 | P19: 5
B20: 3 | C20: Battery, AAA by 4's / pack | D20: 10 | E20: pack | F20: 302 | G20: =D20*F20 -> 3020 | L20: 5 | P20: 5
B21: 4 | C21: Board paper, 220 gsm, Short, White, 10piece / pack | D21: 60 | E21: pack | F21: 75 | G21: =D21*F21 -> 4500 | L21: 30 | P21: 30
B22: 5 | C22: Bond paper, white,long, 80 gsm, 24 substance | D22: 70 | E22: ream | F22: 498 | G22: =D22*F22 -> 34860 | L22: 35 | P22: 35
B23: 6 | C23: Calculator, 12 digit | D23: 50 | E23: piece | F23: 670 | G23: =D23*F23 -> 33500 | L23: 25 | P23: 25
B24: 7 | C24: Certificate Holder, 8.5" x 11" | D24: 300 | E24: piece | F24: 65 | G24: =D24*F24 -> 19500 | L24: 150 | P24: 150
B25: 8 | C25: Correction Tape, 150 meters | D25: 30 | E25: piece | F25: 60 | G25: =D25*F25 -> 1800 | L25: 15 | P25: 15
B26: 9 | C26: Printer ink 003, continuous, Black | D26: 30 | E26: piece | F26: 373 | G26: =D26*F26 -> 11190 | L26: 15 | P26: 15
B27: 10 | C27: Printer ink 003, continuous, Cyan | D27: 12 | E27: piece | F27: 381 | G27: =D27*F27 -> 4572 | L27: 6 | P27: 6
B28: 11 | C28: Printer ink 003, continuous, Magenta | D28: 12 | E28: piece | F28: 381 | G28: =D28*F28 -> 4572 | L28: 6 | P28: 6
B29: 12 | C29: Printer ink 003, continuous, Yellow | D29: 12 | E29: piece | F29: 381 | G29: =D29*F29 -> 4572 | L29: 6 | P29: 6
... B54: 37 | C54: Transparent Tape, 1" | D54: 15 | E54: piece | F54: 39 | G54: =D54*F54 -> 585 | L54: 7 | P54: 8
B55: 38 | C55: Scissors, stainless | D55: 5 | E55: piece | F55: 178 | G55: =D55*F55 -> 890 | P55: 5
B56: 39 | C56: Stapler #10, heavy duty | D56: 5 | E56: piece | F56: 478.5 | G56: =D56*F56 -> 2392.5 | P56: 5
B57: 40 | C57: Staple Wire, no. 35, (5000 piece./box) | D57: 9 | E57: box | F57: 80 | G57: =D57*F57 -> 720 | L57: 5 | P57: 4
C58: Total | G58: =SUM(G18:G57) -> 249991
A61: 50203070 | C61: DRUGS AND MEDICINE EXPENSES | G61: 1200000 | H61: BIDDING/SMALL VALUE
B62: 1 | C62: Iron + Folic Acid, 60 mg/400 mcg, film coated, 100's/box | D62: 3580 | E62: box | F62: 300 | G62: =D62*F62 -> 1074000 | J62: =D62 -> 3580
B63: 2 | C63: Calcium Carbonate, 1.25g tablet with 500 mg. elemental calcium, 100's/box | D63: 252 | E63: box | F63: 500 | G63: =D63*F63 -> 126000 | J63: 252
C64: Total | G64: =SUM(G62:G63) -> 1200000
A67: 50203990 | C67: OTHER SUPPLIES AND MATERIALS EXPENSES | G67: 3000000
C68: Recognition and Awarding of Provincial Nutrition Champions | H68: BIDDING/SMALL VALUE
B69: 1 | C69: Plaque 12" | D69: 10 | E69: piece | F69: 5000 | G69: =D69*F69 -> 50000 | O69: 7 | S69: 3
B70: 2 | C70: Plaque 10" | D70: 10 | E70: piece | F70: 4000 | G70: =D70*F70 -> 40000 | O70: 7 | S70: 3
B71: 3 | C71: Plaque 8" | D71: 7 | E71: piece | F71: 3000 | G71: =D71*F71 -> 21000 | O71: 7
C73: Food Commodities for the Tutok Kainan supplementation Program | H73: BIDDING/SMALL VALUE
...

Sheet TB ELIMINATION SERVICES
A1: Republic of the Philippines Provincial Government of Batangas PROVINCIAL HEALTH OFFICE Brgy. Kumintang Ibaba, Batangas City E-mail: pho@batangas.gov.ph | Tel No. (043) 740-2832; (043) 723-2592
A2: PROJECT PROCUREMENT MANAGEMENT PLAN 2026
A3: END USER/UNIT: | C3: PROVINCIAL HEALTH OFFICE
A4: CHARGED TO: | C4: TUBERCULOSIS ELIMINATION PROGRAM
A6: CODE | B6: GENERAL DESCRIPTION | E6: QTY | F6: UNIT | G6: UNIT PRICE | H6: ESTIMATED BUDGET | I6: MODE OF PROCUREMENT | J6: SCHEDULE / MILESTONE OF ACTIVITIES
J7: JAN | K7: FEB | L7: MAR | M7: APR | N7: MAY | O7: JUN | P7: JUL | Q7: AUG | R7: SEP | S7: OCT | T7: NOV | U7: DEC
C8: MAINTENANCE AND OTHER OPERATING EXPENSES
A10: 50202010 | C10: TRAINING EXPENSES | H10: 200000 | I10: BIDDING/SMALL VALUE | J10: x | K10: x | L10: x | M10: x | N10: x | O10: x | P10: x | Q10: x | R10: x | S10: x | T10: x | U10: x
C11: Meals and snacks
C12: Registration Fee
C13: Food and Accomodation
C14: Total | H14: =H10 -> 200000
A16: 50203010 | C16: OFFICE SUPPLIES EXPENSES | H16: 51000 | I16: BIDDING/SMALL VALUE
B17: 1 | C17: Epson L3110 - 003 Black | E17: 13 | F17: bottle | G17: =1000 -> 1000 | H17: =E17*G17 -> 13000 | L17: 13
B18: 2 | C18: Epson L3110 - 003 Yellow | E18: 11 | F18: bottle | G18: 1100 | H18: =E18*G18 -> 12100 | L18: 11
B19: 3 | C19: Epson L3110 - 003 Magenta | E19: 11 | F19: bottle | G19: 1100 | H19: =E19*G19 -> 12100 | L19: 11
B20: 4 | C20: Epson L3110 - 003 Cyan | E20: 11 | F20: bottle | G20: 1100 | H20: =E20*G20 -> 12100 | L20: 11
C21: Total | H21: =SUM(H17:H20) -> 49300
A23: 50203070 | C23: DRUGS AND MEDICINES EXPENSES | H23: 1500000 | I23: BIDDING/SMALL VALUE
B24: 1 | C24: Purified Protein Derivative (PPD), 5TU/.1mL solution / 1ml | E24: 1000 | F24: vial | H24: 500000 | L24: 1000
C25: Anti-TB Drugs for Children
C26: (7 bottles) Rifampicin 200mg/5mL, 120mL
C27: (4 bottles) Pyrazinamide 250mg/5mL, 120mL
C28: (7 bottles) Isoniazid 200mg/5mL, 120mL
B29: 2 | C29: Intensive Phase Anti TB Drugs for Adult: | E29: 210 | F29: box | H29: 411600 | L29: 210
C30: Fixed Dose Combination 4 80's/box
C31: (Rifampicin 150mg, Isoniazid75 mg, Pyrazinamide 400mg,
C32: Ethambutol 275 mg)
B33: 3 | C33: Maintenance Phase Anti TB Drugs for Adult: | E33: 420 | F33: box | H33: 588400 | L33: 420
C34: Fixed Dose Combination 2 80's/box
C35: (Rifampicin 150mg, Isoniazid75 mg)
C36: Total | H36: =SUM(H24:H35) -> 1500000
A38: 50203080 | C38: MEDICAL, DENTAL, & LABORATORY SUPPLIES EXPENSES | H38: 500000 | I38: BIDDING/SMALL VALUE
B39: 1 | C39: BD Insulin Syringe with needle-0.05ml, 100's/box | E39: 273 | F39: box | G39: 1500 | H39: =E39*G39 -> 409500 | L39: 480
B40: 2 | C40: Sputum cup, with red screw cup cover 60ml | E40: 2033 | F40: piece | G40: 15 | H40: =E40*G40 -> 30495 | L40: 2075
B41: 3 | C41: Staining Reagent, Ziehl-Neelsen (AFB Staining) | E41: 15 | F41: kit | G41: 4000 | H41: =E41*G41 -> 60000 | L41: 15
C42: Total | H42: =SUM(H39:H41) -> 499995
A44: 50206020 | C44: PRIZES | H44: 100000
B45: 1 | C45: Advocacy on TB Prevention and Control LUNG MONTH CELEBRATION | J45: x | K45: x | L45: x | M45: x | N45: x | O45: x | P45: x | Q45: x | R45: x | S45: x | T45: x | U45: x
C46: Cash Prizes for TB Program Top Performers
...

Sheet HSFES
A1: Republic of the Philippines Provincial Government of Batangas PROVINCIAL HEALTH OFFICE Brgy. Kumintang Ibaba, Batangas City E-mail: pho@batangas.gov.ph | Tel No. (043) 740-2832; (043) 723-2592
A2: PROJECT PROCUREMENT MANAGEMENT PLAN 2026
A3: END USER/UNIT: | C3: PROVINCIAL HEALTH OFFICE
A4: CHARGED TO: | C4: HEALTH SERVICES AND FACILITIES ENHANCEMENT SERVICES
A6: CODE | B6: GENERAL DESCRIPTION | E6: QTY | F6: UNIT | G6: UNIT PRICE | H6: ESTIMATED BUDGET | I6: MODE OF PROCUREMENT | J6: SCHEDULE / MILESTONE OF ACTIVITIES
J7: JAN | K7: FEB | L7: MAR | M7: APR | N7: MAY | O7: JUN | P7: JUL | Q7: AUG | R7: SEP | S7: OCT | T7: NOV | U7: DEC
C8: MAINTENANCE AND OTHER OPERATING EXPENSES
A10: 50202010 | C10: TRAINING EXPENSES | H10: 700000 | I10: BIDDING/SMALL VALUE | J10: x | K10: x | L10: x | M10: x | N10: x | O10: x | P10: x | Q10: x | R10: x | S10: x | T10: x | U10: x
C11: Meals and Accomodation/ Food and Venue
C12: Training Materials
C14: Total | H14: 700000
A16: 50203070 | C16: DRUGS AND MEDICINE EXPENSES | H16: 2500000
C18: Senior and Persons with Disabilities (PWD) Program | I18: BIDDING/SMALL VALUE
C19: Anti Flu Vaccine | E19: 200 | F19: vial | G19: 1000 | H19: =E19*G19 -> 200000 | K19: 200
C20: Anti Pneumonia Vaccine | E20: 150 | F20: vial | G20: 2000 | H20: =E20*G20 -> 300000 | K20: 150
C23: Rabies Prevention and Control Program | I23: BIDDING/SMALL VALUE
C24: Anti-Rabies Vaccine | E24: 440 | F24: vials | G24: 3600 | H24: =E24*G24 -> 1584000 | K24: 440
C25: Erig Vaccine - Equirab | E25: 200 | F25: vials | G25: 2000 | H25: =E25*G25 -> 400000 | K25: 200
C26: Tetanus Toxoid 0.5ml ampule by 10s | E26: 150 | F26: vials | G26: 100 | H26: =E26*G26 -> 15000 | K26: 150
C27: Total | H27: =SUM(H19:H26) -> 2499000
A29: 50203080 | C29: MEDICAL, DENTAL, AND LABORATORY SUPPLIES EXPENSES | H29: 2500000
C30: Volunteer Blood Services Program | I30: BIDDING/SMALL VALUE
C31: Hemoglobin Analyzer Microcuvette | E31: 2 | F31: box | G31: =12500*1.4 -> 17500 | H31: =E31*G31 -> 35000 | K31: 2
C32: Typing Sera | D32: 10 ml (Anti-A, Anti-B, Anti-D) | E32: 20 | F32: set | G32: =(30000/20)*1.4 -> 2100 | H32: =E32*G32 -> 42000 | K32: =E32 -> 20
C34: Non-communicable Disease Program | I34: BIDDING/SMALL VALUE
C35: ECG Paper | D35: 110mmx20m | E35: 75 | F35: roll | G35: 560 | H35: =E35*G35 -> 42000 | K35: =E35 -> 75
C36: Glass Slides | D36: 72 | E36: 7 | F36: box | G36: 150 | H36: =E36*G36 -> 1050 | K36: =E36 -> 7
C37: Cotton Applicator | D37: 100's | E37: 5 | F37: box | G37: 250 | H37: =E37*G37 -> 1250 | K37: =E37 -> 5
C38: Bleaching solution | D38: 1 gallon | E38: 1 | F38: gallon | G38: 200 | H38: =E38*G38 -> 200 | K38: =E38 -> 1
C39: Surgical Gloves | D39: sterile, size 6 | E39: 1 | F39: box | G39: 100 | H39: =E39*G39 -> 100 | K39: =E39 -> 1
C40: Surgical Gloves | D40: sterile, size 7 | E40: 1 | F40: box | G40: 100 | H40: =E40*G40 -> 100 | K40: =E40 -> 1
C41: Surgical Gloves | D41: sterile, size 8 | E41: 1 | F41: box | G41: 100 | H41: =E41*G41 -> 100 | K41: =E41 -> 1
C44: Senior and Persons with Disabilities (PWD) Program | I44: BIDDING/SMALL VALUE
C45: Wheel Chair | D45: for adult, heavy duty | E45: 12 | F45: piece | G45: 6000 | H45: =E45*G45 -> 72000 | M45: 12
C46: Pediatric Wheel Chair | D46: heavy duty | E46: 12 | F46: piece | G46: 6000 | H46: =E46*G46 -> 72000 | M46: 12
C47: Quad Cane | D47: adjustable height, contoured handle, heavy duty | E47: 25 | F47: piece | G47: 1500 | H47: =E47*G47 -> 37500 | M47: 25
C48: Crutch Aid Medical Walker | D48: stainless steel, height adjustable | E48: 15 | F48: piece | G48: 2500 | H48: =E48*G48 -> 37500 | M48: 15
C49: Wellness Kit | D49: for seniors | E49: 25 | F49: kit | G49: 3500 | H49: =E49*G49 -> 87500 | M49: 25
C50: Contents per kit:
C51: -Storage box -Standard Pulse Oximeter, Large SPO2 and PR display with bar graph display, Multiple applications in hospital, home, community medical treatment and sports treatment, Accurate measurement of SPO2 and PR with storage and lanyard -2 boxes of Food and supplement syrup per Senior-12 Sachets of 15ml Syrup -Resistance Band (8-word latex resistance band elastic gym equipment) -Calming oil, oil soothes and relaxes 10 ml roll that stress away, 2 pcs. -Herbal Nasal Inhaler with essential oils (natural remedy for headache, sinus, fever and flu) 10 ml -Turmeric tea powder, 10-in-1 Turmeric Tea is composed of 10 different powerful herbs: Pandan, Sambong, Lagundi, Banaba, Ginger, Malunggay, Gynura Procumbens, Lemongrass, Peppermint and Turmeric, (400g pack) -Stevia, 100% Natural Zero Calorie Sweetener , Stevia Leaf Extract Sweetener, Erythritol Sweetener, Sugar Substitute, Sugar Free, Diabetes Friendly, Sugar Alternative, 100sticks/box -Moringa capsule, 500mg., good for 1month -Milk for Senior Citizen, 150 g
...

Sheet PHO-PROPER FUND
A1: Republic of the Philippines Provincial Government of Batangas PROVINCIAL HEALTH OFFICE Brgy. Kumintang Ibaba, Batangas City E-mail: pho@batangas.gov.ph | Tel No. (043) 740-2832; (043) 723-2592
A2: PROJECT PROCUREMENT MANAGEMENT PLAN 2025
A3: END USER/UNIT: | C3: PROVINCIAL HEALTH OFFICE - PROPER
A4: CHARGED TO: | C4: GENERAL FUND - PHO-PROPER
A6: CODE | B6: GENERAL DESCRIPTION | E6: QTY | F6: UNIT | G6: UNIT PRICE | H6: ESTIMATED BUDGET | I6: MODE OF PROCUREMENT | J6: SCHEDULE / MILESTONE OF ACTIVITIES
J7: JAN | K7: FEB | L7: MAR | M7: APR | N7: MAY | O7: JUN | P7: JUL | Q7: AUG | R7: SEP | S7: OCT | T7: NOV | U7: DEC
C8: MAINTENANCE AND OTHER OPERATING EXPENSES
A10: 50201010 | C10: TRAVELING EXPENSES - LOCAL | G10: 0 | H10: 1200000
A12: ='Cover Page'!A10 -> 50203020 | C12: ACCOUNTABLE FORMS EXPENSES | H12: 10000 | I12: BIDDING/SHOPPING/ SMALL VALUE
A14: ='Cover Page'!A11 -> 50203030 | C14: NON-ACCOUNTABLE FORMS EXPENSES | H14: 475000 | I14: BIDDING/SHOPPING/ SMALL VALUE
A16: ='Cover Page'!A14 -> 50203090 | C16: FUEL, OIL AND LUBRICANTS EXPENSES | H16: 3500000 | I16: BIDDING/SHOPPING/ SMALL VALUE
A18: 50205020 | C18: TELEPHONE EXPENSES | H18: 316000
A20: 50205030 | C20: INTERNET SUBSCRIPTION EXPENSES | H20: 300000
A22: 50205040 | C22: CABLE, SATELLITE, TELEGRAPH AND RADIO EXPENSES | H22: 20000 | I22: SHOPPING
A24: ='Cover Page'!A19 -> 50206020 | C24: PRIZES | H24: 210000 | I24: BIDDING/SHOPPING/ SMALL VALUE
C26: REPAIRS AND MAINTENANCE
A27: ='Cover Page'!A20 -> 50213040 | C27: BUILDING AND OTHER STRUCTURES | H27: 3200000 | I27: BIDDING/SHOPPING/ SMALL VALUE
A29: ='Cover Page'!A10 -> 50203020 | C29: MACHINERY AND EQUIPMENT | H29: 400000 | I29: BIDDING/SHOPPING/ SMALL VALUE
A31: ='Cover Page'!A11 -> 50203030 | C31: TRANSPORTATION EQUIPMENT | H31: 750000 | I31: BIDDING/SHOPPING/ SMALL VALUE
A33: 50216010 | C33: TAXES, DUTIES, AND LICENSES | H33: 25000
A35: 50216020 | C35: FIDELITY BOND PREMIUMS | H35: 100000
A37: 50299030 | C37: PRINTING AND PUBLICATION EXPENSES | H37: 250000 | I37: BIDDING/SHOPPING/ SMALL VALUE
A39: 50299040 | C39: TRANSPORTATION & DELIVERY EXPENSES | H39: 260000 | I39: BIDDING/SHOPPING/ SMALL VALUE
A40: 50299050 | C40: RENT EXPENSES | H40: 750000 | I40: BIDDING/SHOPPING/ SMALL VALUE
A42: ='Cover Page'!A8 -> 50202010 | C42: TRAINING EXPENSES | H42: 250000 | I42: BIDDING/SHOPPING/ SMALL VALUE
C43: Meals and Accomodation/ Food and Venue | E43: =#REF! -> #REF! | F43: pax | G43: =H43/E43 -> #REF! | H43: =#REF! -> #REF! | K43: 350 | P43: 250
C44: Others | H44: 250000
C45: Registration Fee
C46: Total | H46: =SUM(H43:H44) -> #REF!
A48: 50203010 | C48: OFFICE SUPPLIES EXPENSES | H48: 3000000
C49: For use of PHO-Proper | I49: BIDDING/SHOPPING/ SMALL VALUE
C50: All Purpose Sticker | D50: A4 10's/pack | E50: 100 | F50: pack | G50: 77 | H50: =E50*G50 -> 7700 | K50: =E50/2 -> 50 | P50: =E50/2 -> 50
C51: AntiVirus Software | D51: With 2 years License | E51: 2 | F51: piece | G51: 4000 | H51: =E51*G51 -> 8000 | K51: =E51 -> 2 | P51: =E51/2 -> 1
C52: Arch File | D52: Vertical, 2-Ring Binder, 2" Side, Long, Black | E52: 50 | F52: piece | G52: 200 | H52: =E52*G52 -> 10000
C53: Arch File | D53: Vertical, 2-Ring Binder, 2" Side, A4, Black | E53: 30 | F53: piece | G53: 200 | H53: =E53*G53 -> 6000
C54: Ballpen | D54: Black 0.5mm | E54: 220 | F54: piece | G54: 15 | H54: =E54*G54 -> 3300 | O54: 60 | P54: 50 | Q54: 50
C55: Ballpen | D55: Black 0.7mm | E55: 1200 | F55: piece | G55: 11.2 | H55: =E55*G55 -> 13440 | K55: =E55/2 -> 600 | P55: =E55/2 -> 600
C56: Ballpen | D56: Blue 0.7mm | E56: 1200 | F56: piece | G56: 11.2 | H56: =E56*G56 -> 13440 | K56: =E56/2 -> 600 | P56: =E56/2 -> 600
C57: Ballpen | D57: Red 0.7mm | E57: 1200 | F57: piece | G57: 11.2 | H57: =E57*G57 -> 13440 | K57: =E57/2 -> 600 | P57: =E57/2 -> 600
C58: Battery | D58: AA (4piece/pack) | E58: 100 | F58: pack | G58: 191.8 | H58: =E58*G58 -> 19180 | K58: =E58/2 -> 50 | P58: =E58/2 -> 50
...
